<?xml version="1.0"?>
<robot name="ur3">
  <material name="Grey">
    <color rgba="0.7 0.7 0.7 1.0"/>
  </material>

  <link name="base_link">
    <origin xyz="0 0 0" rpy="0 0 0"/>
    <visual>
      <geometry>
        <mesh filename="package://my_ur3/meshes/collision/base.stl" scale="1 1 1"/>
      </geometry>
      <material name="Grey"/>
    </visual>
    <collision>
      <geometry>
        <mesh filename="package://my_ur3/meshes/collision/base.stl" scale="1 1 1"/>
      </geometry>

    </collision>
  </link>

  <link name="link_1">
    <visual>
      <geometry>
        <mesh filename="package://my_ur3/meshes/collision/shoulder.stl" scale="1 1 1"/>
      </geometry>
      <material name="Grey"/>
    </visual>
    <collision>
      <geometry>
        <mesh filename="package://my_ur3/meshes/collision/shoulder.stl" scale="1 1 1"/>
      </geometry>

    </collision>
  </link>

  <link name="link_2">
    <visual>
      <geometry>
        <mesh filename="package://my_ur3/meshes/collision/upperarm.stl" scale="1 1 1"/>
      </geometry>
      <material name="Grey"/>
    </visual>
    <collision>
      <geometry>
        <mesh filename="package://my_ur3/meshes/collision/upperarm.stl" scale="1 1 1"/>
      </geometry>

    </collision>
  </link>

  <link name="link_3">
    <visual>
      <geometry>
        <mesh filename="package://my_ur3/meshes/collision/forearm.stl" scale="1 1 1"/>
      </geometry>
      <material name="Grey"/>
    </visual>
    <collision>
      <geometry>
        <mesh filename="package://my_ur3/meshes/collision/forearm.stl" scale="1 1 1"/>
      </geometry>

    </collision>
  </link>

  <link name="link_4">
    <visual>
      <geometry>
        <mesh filename="package://my_ur3/meshes/collision/wrist1.stl" scale="1 1 1"/>
      </geometry>
      <material name="Grey"/>
    </visual>
    <collision>
      <geometry>
        <mesh filename="package://my_ur3/meshes/collision/wrist1.stl" scale="1 1 1"/>
      </geometry>
      
    </collision>
  </link>

  <link name="link_5">
    <visual>
      <geometry>
        <mesh filename="package://my_ur3/meshes/collision/wrist2.stl" scale="1 1 1"/>
      </geometry>
      <material name="Grey"/>
    </visual>
    <collision>
      <geometry>
        <mesh filename="package://my_ur3/meshes/collision/wrist2.stl" scale="1 1 1"/>
      </geometry>

    </collision>
  </link>

  <link name="link_6">
    <visual>
      <geometry>
        <mesh filename="package://my_ur3/meshes/collision/wrist3.stl" scale="1 1 1"/>
      </geometry>
      <material name="Grey"/>
    </visual>
    <collision>
      <geometry>
        <mesh filename="package://my_ur3/meshes/collision/wrist3.stl" scale="1 1 1"/>
      </geometry>

    </collision>
  </link>

  <joint name="shoulder_pan_joint" type="revolute">
    <parent link="base_link"/>
    <child link="link_1"/>
    <origin xyz="0 0 0.1519" rpy="0 0 0"/>
    <axis xyz="0 0 1"/>
    <limit effort="50.0" velocity="3.0" lower="-3.14" upper="3.14"/>
  </joint>

  <joint name="shoulder_lift_joint" type="revolute">
    <parent link="link_1"/>
    <child link="link_2"/>
    <origin xyz="0 0.1198 0" rpy="0 0 0"/>
    <axis xyz="0 1 0"/>
    <limit effort="50.0" velocity="3.0" lower="-3.14" upper="3.14"/>
  </joint>

  <joint name="elbow_joint" type="revolute">
    <parent link="link_2"/>
    <child link="link_3"/>
    <origin xyz="0 -0.0925 0.24365" rpy="0 0 0"/>
    <axis xyz="0 1 0"/>
    <limit effort="50.0" velocity="3.0" lower="-3.14" upper="3.14"/>
  </joint>

  <joint name="wrist_1_joint" type="revolute">
    <parent link="link_3"/>
    <child link="link_4"/>
    <origin xyz="0 0 0.21325" rpy="0 0 0"/>
    <axis xyz="0 1 0"/>
    <limit effort="50.0" velocity="3.0" lower="-3.14" upper="3.14"/>
  </joint>

  <joint name="wrist_2_joint" type="revolute">
    <parent link="link_4"/>
    <child link="link_5"/>
    <origin xyz="0 0.08505 0" rpy="0 0 0"/>
    <axis xyz="0 0 1"/>
    <limit effort="50.0" velocity="3.0" lower="-3.14" upper="3.14"/>
  </joint>

  <joint name="wrist_3_joint" type="revolute">
    <parent link="link_5"/>
    <child link="link_6"/>
    <origin xyz="0 0 0.08535" rpy="0 0 0"/>
    <axis xyz="0 1 0"/>
    <limit effort="50.0" velocity="3.0" lower="-3.14" upper="3.14"/>
  </joint>

</robot>