<?xml version="1.0"?>
<robot name="ur3">

  <!-- Link 0 -->
  <link name="base_link">
    <inertial>
      <mass value="2.0"/>
      <origin xyz="0 -0.02 0"/>
      <inertia ixx="0.01" ixy="0" ixz="0" iyy="0.01" iyz="0" izz="0.01"/>
    </inertial>
  </link>

  <joint name="shoulder_pan_joint" type="revolute">
    <parent link="base_link"/>
    <child link="link_1"/>
    <origin xyz="0 0 0.1519" rpy="0 0 0"/>
    <axis xyz="0 0 1"/>
    <limit effort="10.0" velocity="1.0" lower="-3.14" upper="3.14"/>
  </joint>

  <!-- Link 1 -->
  <link name="link_1">
    <inertial>
      <mass value="3.42"/>
      <origin xyz="0.13 0 0.1157"/>
      <inertia ixx="0.02" ixy="0" ixz="0" iyy="0.02" iyz="0" izz="0.02"/>
    </inertial>
  </link>

  <joint name="shoulder_lift_joint" type="revolute">
    <parent link="link_1"/>
    <child link="link_2"/>
    <origin xyz="-0.24365 0 0" rpy="0 0 0"/>
    <axis xyz="0 0 1"/>
    <limit effort="10.0" velocity="1.0" lower="-3.14" upper="3.14"/>
  </joint>

  <!-- Link 2 -->
  <link name="link_2">
    <inertial>
      <mass value="1.26"/>
      <origin xyz="0.05 0 0.0238"/>
      <inertia ixx="0.01" ixy="0" ixz="0" iyy="0.01" iyz="0" izz="0.01"/>
    </inertial>
  </link>

  <joint name="elbow_joint" type="revolute">
    <parent link="link_2"/>
    <child link="link_3"/>
    <origin xyz="-0.21325 0 0" rpy="0 0 0"/>
    <axis xyz="0 0 1"/>
    <limit effort="10.0" velocity="1.0" lower="-3.14" upper="3.14"/>
  </joint>

  <!-- Link 3 -->
  <link name="link_3">
    <inertial>
      <mass value="0.8"/>
      <origin xyz="0 0 0.01"/>
      <inertia ixx="0.005" ixy="0" ixz="0" iyy="0.005" iyz="0" izz="0.005"/>
    </inertial>
  </link>

  <joint name="wrist_1_joint" type="revolute">
    <parent link="link_3"/>
    <child link="link_4"/>
    <origin xyz="0 0 0.11235" rpy="1.5708 0 0"/>
    <axis xyz="0 0 1"/>
    <limit effort="10.0" velocity="1.0" lower="-3.14" upper="3.14"/>
  </joint>

  <!-- Link 4 -->
  <link name="link_4">
    <inertial>
      <mass value="0.8"/>
      <origin xyz="0 0 0.01"/>
      <inertia ixx="0.005" ixy="0" ixz="0" iyy="0.005" iyz="0" izz="0.005"/>
    </inertial>
  </link>

  <joint name="wrist_2_joint" type="revolute">
    <parent link="link_4"/>
    <child link="link_5"/>
    <origin xyz="0 0 0.08535" rpy="-1.5708 0 0"/>
    <axis xyz="0 0 1"/>
    <limit effort="10.0" velocity="1.0" lower="-3.14" upper="3.14"/>
  </joint>

    <!-- Link 5 -->
  <link name="link_5">
    <inertial>
      <mass value="0.8"/>
      <origin xyz="0 0 0.01"/>
      <inertia ixx="0.005" ixy="0" ixz="0" iyy="0.005" iyz="0" izz="0.005"/>
    </inertial>
  </link>

  <joint name="wrist_3_joint" type="revolute">
    <parent link="link_5"/>
    <child link="link_6"/>
    <origin xyz="0 0 0.0819" rpy="0 0 0"/>
    <axis xyz="0 0 1"/>
    <limit effort="10.0" velocity="1.0" lower="-3.14" upper="3.14"/>
  </joint>

  <!-- Link 6 (final link) -->
  <link name="link_6">
    <inertial>
      <mass value="0.35"/>
      <origin xyz="0 0 -0.02"/>
      <inertia ixx="0.002" ixy="0" ixz="0" iyy="0.002" iyz="0" izz="0.002"/>
    </inertial>
  </link>

</robot>
